Workbook

Sheet README
A1: xirr-rs golden-value corpus
A3: HOW TO REGENERATE GOLDEN VALUES FROM A REAL SPREADSHEET ENGINE
A4: 1. Open this workbook in Excel, Google Sheets, or LibreOffice Calc.
A5: 2. Let it recalculate. The 'results' sheet column D computes XIRR() natively.
A6: 3. Copy 'results' columns A and D into golden_<engine>.csv (case_id,expected).
A7: 4. A cell showing the numeric-error marker means the engine could not solve it; record NUM.
A9: Column D formula: =IFERROR(XIRR(amount_range, date_range), "NUM")
A10: Guess is left at the engine default of 10%, matching production callers.
A12: Cash flows live on the 'flows' sheet in long format, one row per payment,
A13: grouped by case_id and already in the exact input order the library receives.
A14: Input order is significant: XIRR uses the FIRST row of each block as the
A15: reference date, not the earliest date.
... A18: Cases: 89

Sheet flows
A1: case_id | B1: date | C1: amount
A2: conventional/textbook-3flow | B2: 43831 | C2: -1000
A3: conventional/textbook-3flow | B3: 44197 | C3: 750
A4: conventional/textbook-3flow | B4: 44562 | C4: 500
A5: conventional/one-year-30pct | B5: 43831 | C5: -100
A6: conventional/one-year-30pct | B6: 44197 | C6: 130
A7: conventional/monthly-12 | B7: 44197 | C7: -100
A8: conventional/monthly-12 | B8: 44228 | C8: 20
A9: conventional/monthly-12 | B9: 44256 | C9: 20
A10: conventional/monthly-12 | B10: 44287 | C10: 20
A11: conventional/monthly-12 | B11: 44317 | C11: 20
A12: conventional/monthly-12 | B12: 44348 | C12: 20
A13: conventional/monthly-12 | B13: 44378 | C13: 20
... A481: fuzz/058 | B481: 43558 | C481: 3356

Sheet results
A1: case_id | B1: n_flows | C1: sign_changes | D1: xirr | E1: xnpv_at_xirr
A2: conventional/textbook-3flow | B2: 3 | C2: 1 | D2: =IFERROR(XIRR(flows!$C$2:$C$4,flows!$B$2:$B$4),"NUM") -> 0.17500926 | E2: =IF(ISNUMBER(D2),IFERROR(XNPV(D2,flows!$C$2:$C$4,flows!$B$2:$B$4),"ERR"),"") -> 0
A3: conventional/one-year-30pct | B3: 2 | C3: 1 | D3: =IFERROR(XIRR(flows!$C$5:$C$6,flows!$B$5:$B$6),"NUM") -> 0.29906844 | E3: =IF(ISNUMBER(D3),IFERROR(XNPV(D3,flows!$C$5:$C$6,flows!$B$5:$B$6),"ERR"),"") -> 1.4210855e-14
A4: conventional/monthly-12 | B4: 12 | C4: 1 | D4: =IFERROR(XIRR(flows!$C$7:$C$18,flows!$B$7:$B$18),"NUM") -> 5.0962355 | E4: =IF(ISNUMBER(D4),IFERROR(XNPV(D4,flows!$C$7:$C$18,flows!$B$7:$B$18),"ERR"),"") -> -8.8817842e-16
A5: conventional/quarterly-drawdown | B5: 6 | C5: 1 | D5: =IFERROR(XIRR(flows!$C$19:$C$24,flows!$B$19:$B$24),"NUM") -> 0.085316639 | E5: =IF(ISNUMBER(D5),IFERROR(XNPV(D5,flows!$C$19:$C$24,flows!$B$19:$B$24),"ERR"),"") -> -3.6379788e-12
A6: conventional/leap-year-span | B6: 2 | C6: 1 | D6: =IFERROR(XIRR(flows!$C$25:$C$26,flows!$B$25:$B$26),"NUM") -> 0.14956094 | E6: =IF(ISNUMBER(D6),IFERROR(XNPV(D6,flows!$C$25:$C$26,flows!$B$25:$B$26),"ERR"),"") -> 1.1368684e-13
A7: horizon/30y-50x | B7: 2 | C7: 1 | D7: =IFERROR(XIRR(flows!$C$27:$C$28,flows!$B$27:$B$28),"NUM") -> 0.13918997 | E7: =IF(ISNUMBER(D7),IFERROR(XNPV(D7,flows!$C$27:$C$28,flows!$B$27:$B$28),"ERR"),"") -> 2.0463631e-12
A8: horizon/50y-50x | B8: 2 | C8: 1 | D8: =IFERROR(XIRR(flows!$C$29:$C$30,flows!$B$29:$B$30),"NUM") -> 0.081322433 | E8: =IF(ISNUMBER(D8),IFERROR(XNPV(D8,flows!$C$29:$C$30,flows!$B$29:$B$30),"ERR"),"") -> 3.4106051e-13
A9: horizon/5-day-10pct | B9: 2 | C9: 1 | D9: =IFERROR(XIRR(flows!$C$31:$C$32,flows!$B$31:$B$32),"NUM") -> 1050.1532 | E9: =IF(ISNUMBER(D9),IFERROR(XNPV(D9,flows!$C$31:$C$32,flows!$B$31:$B$32),"ERR"),"") -> 1.1368684e-13
A10: horizon/1-day | B10: 2 | C10: 1 | D10: =IFERROR(XIRR(flows!$C$33:$C$34,flows!$B$33:$B$34),"NUM") -> 0.44025131 | E10: =IF(ISNUMBER(D10),IFERROR(XNPV(D10,flows!$C$33:$C$34,flows!$B$33:$B$34),"ERR"),"") -> 1.1368684e-13
A11: horizon/tiny-basis-10y | B11: 3 | C11: 1 | D11: =IFERROR(XIRR(flows!$C$35:$C$37,flows!$B$35:$B$37),"NUM") -> 2.7111359 | E11: =IF(ISNUMBER(D11),IFERROR(XNPV(D11,flows!$C$35:$C$37,flows!$B$35:$B$37),"ERR"),"") -> -2.220446e-16
A12: rate/near-zero-positive | B12: 2 | C12: 1 | D12: =IFERROR(XIRR(flows!$C$38:$C$39,flows!$B$38:$B$39),"NUM") -> 9.9726776e-08 | E12: =IF(ISNUMBER(D12),IFERROR(XNPV(D12,flows!$C$38:$C$39,flows!$B$38:$B$39),"ERR"),"") -> -1.1368684e-13
A13: rate/exact-zero | B13: 2 | C13: 1 | D13: =IFERROR(XIRR(flows!$C$40:$C$41,flows!$B$40:$B$41),"NUM") -> 2.1696732e-17 | E13: =IF(ISNUMBER(D13),IFERROR(XNPV(D13,flows!$C$40:$C$41,flows!$B$40:$B$41),"ERR"),"") -> 0
A14: rate/near-zero-negative | B14: 2 | C14: 1 | D14: =IFERROR(XIRR(flows!$C$42:$C$43,flows!$B$42:$B$43),"NUM") -> -9.9726776e-08 | E14: =IF(ISNUMBER(D14),IFERROR(XNPV(D14,flows!$C$42:$C$43,flows!$B$42:$B$43),"ERR"),"") -> 0
A15: rate/near-total-loss | B15: 2 | C15: 1 | D15: =IFERROR(XIRR(flows!$C$44:$C$45,flows!$B$44:$B$45),"NUM") -> NUM | E15: =IF(ISNUMBER(D15),IFERROR(XNPV(D15,flows!$C$44:$C$45,flows!$B$44:$B$45),"ERR"),"")
A16: rate/deep-negative | B16: 3 | C16: 1 | D16: =IFERROR(XIRR(flows!$C$46:$C$48,flows!$B$46:$B$48),"NUM") -> -0.81442744 | E16: =IF(ISNUMBER(D16),IFERROR(XNPV(D16,flows!$C$46:$C$48,flows!$B$46:$B$48),"ERR"),"") -> 0
A17: multiroot/classic-100-230-132 | B17: 3 | C17: 2 | D17: =IFERROR(XIRR(flows!$C$49:$C$51,flows!$B$49:$B$51),"NUM") -> 0.10339793 | E17: =IF(ISNUMBER(D17),IFERROR(XNPV(D17,flows!$C$49:$C$51,flows!$B$49:$B$51),"ERR"),"") -> 2.8421709e-14
A18: multiroot/sign-reversal-monthly | B18: 3 | C18: 2 | D18: =IFERROR(XIRR(flows!$C$52:$C$54,flows!$B$52:$B$54),"NUM") -> -0.70240549 | E18: =IF(ISNUMBER(D18),IFERROR(XNPV(D18,flows!$C$52:$C$54,flows!$B$52:$B$54),"ERR"),"") -> 0
A19: multiroot/three-roots | B19: 4 | C19: 3 | D19: =IFERROR(XIRR(flows!$C$55:$C$58,flows!$B$55:$B$58),"NUM") -> -0.57188595 | E19: =IF(ISNUMBER(D19),IFERROR(XNPV(D19,flows!$C$55:$C$58,flows!$B$55:$B$58),"ERR"),"") -> -1.8189894e-12
A20: multiroot/pe-recall | B20: 4 | C20: 3 | D20: =IFERROR(XIRR(flows!$C$59:$C$62,flows!$B$59:$B$62),"NUM") -> 2.4825548 | E20: =IF(ISNUMBER(D20),IFERROR(XNPV(D20,flows!$C$59:$C$62,flows!$B$59:$B$62),"ERR"),"") -> -1.4210855e-14
A21: multiroot/five-flips | B21: 5 | C21: 4 | D21: =IFERROR(XIRR(flows!$C$63:$C$67,flows!$B$63:$B$67),"NUM") -> -0.96428712 | E21: =IF(ISNUMBER(D21),IFERROR(XNPV(D21,flows!$C$63:$C$67,flows!$B$63:$B$67),"ERR"),"") -> 0
A22: multiroot/capital-call-mid | B22: 4 | C22: 3 | D22: =IFERROR(XIRR(flows!$C$68:$C$71,flows!$B$68:$B$71),"NUM") -> 0.13008746 | E22: =IF(ISNUMBER(D22),IFERROR(XNPV(D22,flows!$C$68:$C$71,flows!$B$68:$B$71),"ERR"),"") -> 2.2737368e-13
A23: scale/1e0-conventional | B23: 3 | C23: 1 | D23: =IFERROR(XIRR(flows!$C$72:$C$74,flows!$B$72:$B$74),"NUM") -> 0.17500926 | E23: =IF(ISNUMBER(D23),IFERROR(XNPV(D23,flows!$C$72:$C$74,flows!$B$72:$B$74),"ERR"),"") -> 0
A24: scale/1e0-multiroot | B24: 4 | C24: 3 | D24: =IFERROR(XIRR(flows!$C$75:$C$78,flows!$B$75:$B$78),"NUM") -> 2.4646907 | E24: =IF(ISNUMBER(D24),IFERROR(XNPV(D24,flows!$C$75:$C$78,flows!$B$75:$B$78),"ERR"),"") -> -1.9895197e-13
A25: scale/1e3-conventional | B25: 3 | C25: 1 | D25: =IFERROR(XIRR(flows!$C$79:$C$81,flows!$B$79:$B$81),"NUM") -> 0.17500926 | E25: =IF(ISNUMBER(D25),IFERROR(XNPV(D25,flows!$C$79:$C$81,flows!$B$79:$B$81),"ERR"),"") -> -2.3283064e-10
A26: scale/1e3-multiroot | B26: 4 | C26: 3 | D26: =IFERROR(XIRR(flows!$C$82:$C$85,flows!$B$82:$B$85),"NUM") -> 2.4646907 | E26: =IF(ISNUMBER(D26),IFERROR(XNPV(D26,flows!$C$82:$C$85,flows!$B$82:$B$85),"ERR"),"") -> 2.0372681e-10
A27: scale/1e6-conventional | B27: 3 | C27: 1 | D27: =IFERROR(XIRR(flows!$C$86:$C$88,flows!$B$86:$B$88),"NUM") -> 0.17500926 | E27: =IF(ISNUMBER(D27),IFERROR(XNPV(D27,flows!$C$86:$C$88,flows!$B$86:$B$88),"ERR"),"") -> 0
A28: scale/1e6-multiroot | B28: 4 | C28: 3 | D28: =IFERROR(XIRR(flows!$C$89:$C$92,flows!$B$89:$B$92),"NUM") -> 2.4646907 | E28: =IF(ISNUMBER(D28),IFERROR(XNPV(D28,flows!$C$89:$C$92,flows!$B$89:$B$92),"ERR"),"") -> 4.4703484e-08
A29: scale/1e9-conventional | B29: 3 | C29: 1 | D29: =IFERROR(XIRR(flows!$C$93:$C$95,flows!$B$93:$B$95),"NUM") -> 0.17500926 | E29: =IF(ISNUMBER(D29),IFERROR(XNPV(D29,flows!$C$93:$C$95,flows!$B$93:$B$95),"ERR"),"") -> -6.1035156e-05
A30: scale/1e9-multiroot | B30: 4 | C30: 3 | D30: =IFERROR(XIRR(flows!$C$96:$C$99,flows!$B$96:$B$99),"NUM") -> 2.4646907 | E30: =IF(ISNUMBER(D30),IFERROR(XNPV(D30,flows!$C$96:$C$99,flows!$B$96:$B$99),"ERR"),"") -> 0.00016021729
A31: scale/1e12-conventional | B31: 3 | C31: 1 | D31: =IFERROR(XIRR(flows!$C$100:$C$102,flows!$B$100:$B$102),"NUM") -> 0.17500926 | E31: =IF(ISNUMBER(D31),IFERROR(XNPV(D31,flows!$C$100:$C$102,flows!$B$100:$B$102),"ERR"),"") -> 0.25
A32: scale/1e12-multiroot | B32: 4 | C32: 3 | D32: =IFERROR(XIRR(flows!$C$103:$C$106,flows!$B$103:$B$106),"NUM") -> 2.4646907 | E32: =IF(ISNUMBER(D32),IFERROR(XNPV(D32,flows!$C$103:$C$106,flows!$B$103:$B$106),"ERR"),"") -> -0.0390625
A33: scale/sub-cent | B33: 2 | C33: 1 | D33: =IFERROR(XIRR(flows!$C$107:$C$108,flows!$B$107:$B$108),"NUM") -> 0.24923813 | E33: =IF(ISNUMBER(D33),IFERROR(XNPV(D33,flows!$C$107:$C$108,flows!$B$107:$B$108),"ERR"),"") -> 0
A34: edge/zero-amounts-interleaved | B34: 4 | C34: 0 | D34: =IFERROR(XIRR(flows!$C$109:$C$112,flows!$B$109:$B$112),"NUM") -> 0.13997083 | E34: =IF(ISNUMBER(D34),IFERROR(XNPV(D34,flows!$C$109:$C$112,flows!$B$109:$B$112),"ERR"),"") -> 0
A35: edge/duplicate-dates | B35: 3 | C35: 1 | D35: =IFERROR(XIRR(flows!$C$113:$C$115,flows!$B$113:$B$115),"NUM") -> 0.13997083 | E35: =IF(ISNUMBER(D35),IFERROR(XNPV(D35,flows!$C$113:$C$115,flows!$B$113:$B$115),"ERR"),"") -> 0
A36: edge/many-flows-60 | B36: 60 | C36: 1 | D36: =IFERROR(XIRR(flows!$C$116:$C$175,flows!$B$116:$B$175),"NUM") -> 0.012937937 | E36: =IF(ISNUMBER(D36),IFERROR(XNPV(D36,flows!$C$116:$C$175,flows!$B$116:$B$175),"ERR"),"") -> 1.5347723e-12
A37: edge/trailing-zero | B37: 3 | C37: 1 | D37: =IFERROR(XIRR(flows!$C$176:$C$178,flows!$B$176:$B$178),"NUM") -> 0.19940237 | E37: =IF(ISNUMBER(D37),IFERROR(XNPV(D37,flows!$C$176:$C$178,flows!$B$176:$B$178),"ERR"),"") -> 0
A38: nosolution/lease-tail | B38: 3 | C38: 1 | D38: =IFERROR(XIRR(flows!$C$179:$C$181,flows!$B$179:$B$181),"NUM") -> NUM | E38: =IF(ISNUMBER(D38),IFERROR(XNPV(D38,flows!$C$179:$C$181,flows!$B$179:$B$181),"ERR"),"")
A39: nosolution/all-tiny-outflow | B39: 3 | C39: 1 | D39: =IFERROR(XIRR(flows!$C$182:$C$184,flows!$B$182:$B$184),"NUM") -> 9.3313688e+10 | E39: =IF(ISNUMBER(D39),IFERROR(XNPV(D39,flows!$C$182:$C$184,flows!$B$182:$B$184),"ERR"),"") -> 1.9079841e-17
A40: fuzz/000 | B40: 4 | C40: 2 | D40: =IFERROR(XIRR(flows!$C$185:$C$188,flows!$B$185:$B$188),"NUM") -> NUM | E40: =IF(ISNUMBER(D40),IFERROR(XNPV(D40,flows!$C$185:$C$188,flows!$B$185:$B$188),"ERR"),"")
...
